<?xml version="1.0" ?>
<sdf version="1.7">
    <!-- <plugin
        filename="ignition-gazebo-imu-system"
        name="ignition::gazebo::systems::Imu">
    </plugin> -->

    <model name="Turtlebot3_Burger" canonical_link='base_footprint'>
        
        <!-- <pose>0.5 -1.6 0.01 0 0 0</pose> -->
        <pose>0 0 0.01 0 0 0</pose>

        <link name="base_footprint"/>

        <joint name="base_joint" type="fixed">
            <parent>base_footprint</parent>
            <child>base_link</child>
            <pose>0.0 0.0 0.010 0 0 0</pose>
        </joint>

        <link name="base_link">
            <inertial>
                <pose>-0.032 0 0.070 0 0 0</pose>
                <inertia>
                <ixx>2.2124416e-03</ixx>
                <ixy>-1.2294101e-05</ixy>
                <ixz>3.4938785e-05</ixz>
                <iyy>2.1193702e-03</iyy>
                <iyz>-5.0120904e-06</iyz>
                <izz>2.0064271e-03</izz>
                </inertia>
                <mass>8.2573504e-01</mass>
            </inertial>
        
            <collision name="base_collision">
                <pose>-0.032 0 0.070 0 0 0</pose>
                <geometry>
                <box>
                    <!-- <size>0.140 0.140 0.143</size> -->
                    <size>0.140 0.140 0.140</size>
                </box>
                </geometry>
            </collision>
        
            <visual name="base_visual">
                <pose>-0.032 0 0 0 0 0</pose>
                <geometry>
                <mesh>
                    <uri>meshes/burger_base.dae</uri>
                    <scale>0.001 0.001 0.001</scale>
                </mesh>
                <material>
                    <ambient>0.0 0.4 0.0 1.0</ambient>
                    <diffuse>0.0 0.4 0.0 1.0</diffuse>
                    <specular>0.0 0.4 0.0 1.0</specular>
                </material>
                </geometry>
            </visual>
        </link>

        <joint name="wheel_left_joint" type="revolute">
            <parent>base_link</parent>
            <child>wheel_left_link</child>
            <pose>0 0.08 0.023 -1.57 0 0</pose>
            <axis>
                <xyz expressed_in='__model__'>0 1 0</xyz> <!--can be defined as any frame or even arbitrary frames-->
            </axis>
        </joint>

        <link name="wheel_left_link">
            <inertial>
                <pose>0 0.08 0.023 -1.57 0 0</pose>
                <inertia>
                    <ixx>1.1175580e-05</ixx>
                    <ixy>-4.2369783e-11</ixy>
                    <ixz>-5.9381719e-09</ixz>
                    <iyy>1.1192413e-05</iyy>
                    <iyz>-1.4400107e-11</iyz>
                    <izz>2.0712558e-05</izz>
                </inertia>
                <mass>2.8498940e-02</mass>
            </inertial>
        
            <collision name="wheel_left_collision">
                <pose>0 0.08 0.023 -1.57 0 0</pose>
                <geometry>
                <cylinder>
                    <radius>0.033</radius>
                    <length>0.018</length>
                </cylinder>
                </geometry>
                <surface>
                <!-- This friction pamareter don't contain reliable data!! -->
                    <friction>
                    <ode>
                        <mu>100000.0</mu>
                        <mu2>100000.0</mu2>
                        <fdir1>0 0 0</fdir1>
                        <slip1>0.0</slip1>
                        <slip2>0.0</slip2>
                    </ode>
                </friction>
                </surface>
            </collision>
        
            <visual name="wheel_left_visual">
                <pose>0 0.08 0.023 0 0 0</pose>
                <geometry>
                    <mesh>
                        <uri>meshes/left_tire.dae</uri>
                        <scale>0.001 0.001 0.001</scale>
                    </mesh>
                </geometry>
                <material>
                    <ambient>0.3 0.3 0.3 1.0</ambient>
                    <diffuse>0.3 0.3 0.3 1.0</diffuse>
                    <specular>0.3 0.3 0.3 1.0</specular>
                </material>
            </visual>
        </link>

        <joint name="wheel_right_joint" type='revolute'>
            <parent>base_link</parent>
            <child>wheel_right_link</child>
            <pose>0.0 -0.08 0.023 -1.57 0 0</pose>
            <axis>
                <xyz expressed_in='__model__'>0 1 0</xyz> <!--can be defined as any frame or even arbitrary frames-->
                <limit>
                    <lower>-1.79769e+308</lower>    <!--negative infinity-->
                    <upper>1.79769e+308</upper>     <!--positive infinity-->
                </limit>
            </axis>
        </joint>

        <link name="wheel_right_link">
            <inertial>
                <pose>0.0 -0.08 0.023 -1.57 0 0</pose>
                <inertia>
                    <ixx>1.1175580e-05</ixx>
                    <ixy>-4.2369783e-11</ixy>
                    <ixz>-5.9381719e-09</ixz>
                    <iyy>1.1192413e-05</iyy>
                    <iyz>-1.4400107e-11</iyz>
                    <izz>2.0712558e-05</izz>
                </inertia>
                <mass>2.8498940e-02</mass>
            </inertial>
            
            <collision name="wheel_right_collision">
                <pose>0.0 -0.08 0.023 -1.57 0 0</pose>
                <geometry>
                    <cylinder>
                        <radius>0.033</radius>
                        <length>0.018</length>
                    </cylinder>
                </geometry>
                <surface>
                <!-- This friction pamareter don't contain reliable data!! -->
                    <friction>
                    <ode>
                        <mu>100000.0</mu>
                        <mu2>100000.0</mu2>
                        <fdir1>0 0 0</fdir1>
                        <slip1>0.0</slip1>
                        <slip2>0.0</slip2>
                    </ode>
                </friction>
                </surface>
            </collision>
        
            <visual name="wheel_right_visual">
                <pose>0.0 -0.08 0.023 0 0 0</pose>
                <geometry>
                    <mesh>
                        <uri>meshes/right_tire.dae</uri>
                        <scale>0.001 0.001 0.001</scale>
                    </mesh>
                </geometry>
                <material>
                    <ambient>0.3 0.3 0.3 1.0</ambient>
                    <diffuse>0.3 0.3 0.3 1.0</diffuse>
                    <specular>0.3 0.3 0.3 1.0</specular>
                </material>
            </visual>
        </link>

        <joint name="caster_back_joint" type="fixed">
            <parent>base_link</parent>
            <child>caster_back_link</child>
            <pose>-0.081 0 -0.004 -1.57 0 0</pose>
        </joint>

        <link name="caster_back_link">
            <inertial>
                <pose>-0.081 0 -0.004 0 0 0</pose>
                <inertia>
                <ixx>0.001</ixx>
                <ixy>0.0</ixy>
                <ixz>0.0</ixz>
                <iyy>0.001</iyy>
                <iyz>0.0</iyz>
                <izz>0.001</izz>
                </inertia>
                <mass>0.005</mass>
            </inertial>
        
            <collision name="caster_back_collision">
                <pose>-0.081 0 -0.004 0 0 0</pose>
                <geometry>
                <box>
                    <size>0.030 0.009 0.020</size>
                </box>
                </geometry>
            </collision>
        </link>

        <joint name="imu_joint" type="fixed">
            <parent>base_link</parent>
            <child>imu_link</child>
            <pose>-0.032 0 0.068 0 0 0</pose>
        </joint>

        <link name="imu_link">
            <!-- <sensor name="imu" type="imu">
                <always_on>1</always_on>
                <update_rate>0</update_rate>
                <visualize>true</visualize>
                <topic>imu</topic>
            </sensor> -->
        </link>

        <joint name="scan_joint" type="fixed">
            <parent>base_link</parent>
            <child>base_scan</child>
            <pose>-0.032 0 0.171 0 0 0</pose>
        </joint>

        <link name="base_scan">
            <inertial>
                <pose>-0.020 0 0.161 0 0 0</pose>
                <inertia>
                <ixx>0.001</ixx>
                <ixy>0.000</ixy>
                <ixz>0.000</ixz>
                <iyy>0.001</iyy>
                <iyz>0.000</iyz>
                <izz>0.001</izz>
                </inertia>
                <mass>0.114</mass>
            </inertial>
        
            <collision name="base_scan_collision">
                <!-- <pose>0.015 0 -0.0065 0 0 0</pose> -->
                <pose>-0.020 0 0.161 0 0 0</pose>
                <geometry>
                <cylinder>
                    <radius>0.055</radius>
                    <length>0.0315</length>
                </cylinder>
                </geometry>
            </collision>
        
            <visual name="base_scan_visual">
                <pose>-0.032 0 0.171 0 0 0</pose>
                <geometry>
                <mesh>
                    <uri>meshes/lds.dae</uri>
                    <scale>0.001 0.001 0.001</scale>
                </mesh>
                </geometry>
                <material>
                <ambient>0.3 0.3 0.3 1.0</ambient>
                <diffuse>0.3 0.3 0.3 1.0</diffuse>
                <specular>0.3 0.3 0.3 1.0</specular>
                </material>
            </visual>
    
            <!-- <sensor name="hls_lfcd_lds" type="gpu_lidar">
                <always_on>1</always_on>
                <visualize>0</visualize>
                <pose>-0.032 0 0.171 0 0 0</pose>
                <topic>scan</topic>
                <update_rate>5</update_rate>
                <ray>
                <scan>
                    <horizontal>
                    <samples>360</samples>
                    <resolution>1</resolution>
                    <min_angle>0.0</min_angle>
                    <max_angle>6.28319</max_angle>
                    </horizontal>
                </scan>
                <range>
                    <min>0.120</min>
                    <max>3.5</max>
                    <resolution>0.015</resolution>
                </range>
                <noise>
                    <type>gaussian</type>
                    <mean>0.0</mean>
                    <stddev>0.01</stddev>
                </noise>
                </ray>
            </sensor> -->
        </link>

        <joint name="thermal_camera_joint" type="fixed">
            <parent>base_link</parent>
            <child>thermal_camera_link</child>
            <pose>0.032 0 0.2 0 0 0</pose>
        </joint>

        <link name="thermal_camera_link">
            <inertial>
                <pose>0.020 0 0.181 0 0 0</pose>
                <inertia>
                <ixx>0.001</ixx>
                <ixy>0.000</ixy>
                <ixz>0.000</ixz>
                <iyy>0.001</iyy>
                <iyz>0.000</iyz>
                <izz>0.001</izz>
                </inertia>
                <mass>0.114</mass>
            </inertial>
            <!-- <pose>-0.032 0 0.181 0 0 0</pose> -->
            <collision name="thermal_camera_collision">
                <pose>0.020 0 0.2 0 0 0</pose>
                <geometry>
                    <box>
                        <size>0.025 0.025 0.025</size>
                    </box>
                </geometry>
            </collision>
            <visual name="thermal_camera_visual">
                <pose>0.032 0 0.2 0 0 0</pose>
                <geometry>
                    <box>
                        <size>0.025 0.025 0.025</size>
                    </box>
                </geometry>
            </visual>
            <sensor name="thermal_camera_sensor" type="thermal">
                <camera>
                  <horizontal_fov>2.0472</horizontal_fov>
                  <image>
                    <width>320</width>
                    <height>240</height>
                    <format>L16</format>
                  </image>
                  <clip>
                    <near>0.1</near>
                    <far>100</far>
                  </clip>
                </camera>
                <always_on>1</always_on>
                <update_rate>30</update_rate>
                <visualize>false</visualize>
                <topic>thermal_camera</topic>
                <plugin
                    filename="ignition-gazebo-thermal-sensor-system"
                    name="ignition::gazebo::systems::ThermalSensor">
                    <min_temp>253.15</min_temp>
                    <max_temp>673.15</max_temp>
                    <resolution>3.0</resolution>
                </plugin>
            </sensor>
        </link>

        <plugin
        filename="ignition-gazebo-diff-drive-system"
        name="ignition::gazebo::systems::DiffDrive">
            <left_joint>wheel_left_joint</left_joint>
            <right_joint>wheel_right_joint</right_joint>
            <wheel_separation>0.16</wheel_separation>
            <wheel_radius>0.033</wheel_radius>
            <odom_publish_frequency>40</odom_publish_frequency>
            <topic>cmd_vel</topic>
            <odom_topic>odom</odom_topic>
            <tf_topic>tf</tf_topic>
            <frame_id>odom</frame_id>
            <child_frame_id>base_footprint</child_frame_id>
        </plugin>

        <!-- <plugin
        filename="libignition-gazebo-sensors-system.so"
        name="ignition::gazebo::systems::Sensors">
            <render_engine>ogre2</render_engine>
        </plugin> -->

        <!-- <plugin
        filename="ignition-gazebo-joint-state-publisher-system"
        name="ignition::gazebo::systems::JointStatePublisher">
            <joint_name>base_joint</joint_name>
            <joint_name>wheel_left_joint</joint_name>
            <joint_name>wheel_right_joint</joint_name>
        </plugin> -->
    </model>
</sdf>